---
title: 27 测一测 对于catch作用域的理解
date: 2020-03-27
isTimeLine: true
sidebar: true
sidebarDepth: 1
isShowComments: true
tags:
- catch
- 作用域
- 打印结果
categories:
- 每日一题
---

```js
let x, y;
try {
 throw new Error();
} catch (x) {
    x = 1
    y = 2
   console.log(x)
}
console.log(x)
console.log(y)
```

<!-- ![题目](/my-vue-press-blog/img/accu/2020-03-27-timu.png) -->

> 答案：1 undefined 2

> 解析：

:::tip
catch块接收参数x，当我们传递参数时，这与变量的x不同。

这个变量x是属于catch作用域的。

需要注意的是catch的作用域，其实并不是常见的块作用域，并不能绑定自己的内部声明的变量。

catch创建的块作用域，只对catch的参数有效。

对于在内部声明的变量，catch并没有创建一个新的作用域，只是一个普通的代码块。
:::